Workbook
Name Slicer_Channel: #N/A
Name Slicer_Channel_via_Customer: #N/A
Name Slicer_Created_Month: #N/A
Name Slicer_Market: #N/A
Name Slicer_Market1: #N/A
Name Slicer_Market2: #N/A
Name Slicer_Transaction_Month: #N/A

Sheet Clean_Leads
A1: Lead_ID | B1: Created_Date | C1: Created_Month | D1: Market | E1: Channel | F1: Product | G1: Company_Size | H1: Sales_Rep_ID | I1: Rep_Valid | J1: Lead_Status | K1: Qualified_Flag | L1: Qualified_Date | M1: Opportunity_Date | N1: Won_Date | O1: Lost_Date | P1: Won_Duration_Valid | Q1: Expected_Monthly_Revenue_EUR
A2: LEAD00001 | B2: 45936 | C2: 45931 | D2: United Kingdom | E2: Telesales | F2: Fuel Card | G2: Enterprise | H2: REP004 | I2: =TRUE() -> TRUE | J2: Lost | K2: Yes | L2: 45941 | M2: 45944 | O2: 45967 | P2: =TRUE() -> TRUE | Q2: 10091.73
A3: LEAD00002 | B3: 45999 | C3: 45992 | D3: Czech Republic | E3: Partner | F3: Toll Solution | G3: SME | H3: REP012 | I3: =TRUE() -> TRUE | J3: Opportunity | K3: Yes | L3: 46005 | M3: 46020 | P3: =TRUE() -> TRUE | Q3: 702.99
A4: LEAD00003 | B4: 45960 | C4: 45931 | D4: Netherlands | E4: Telesales | F4: Fleet Expense Card | G4: Mid-Market | H4: REP008 | I4: =TRUE() -> TRUE | J4: Lost | K4: No | O4: 45963 | P4: =TRUE() -> TRUE | Q4: 2285.31
A5: LEAD00004 | B5: 45892 | C5: 45870 | D5: United Kingdom | E5: Partner | F5: Toll Solution | G5: Enterprise | H5: REP006 | I5: =TRUE() -> TRUE | J5: Lost | K5: Yes | L5: 45902 | M5: 45915 | O5: 45920 | P5: =TRUE() -> TRUE | Q5: 5065.21
A6: LEAD00005 | B6: 45946 | C6: 45931 | D6: Germany | E6: Direct Sales | F6: Fleet Expense Card | G6: SME | H6: REP001 | I6: =TRUE() -> TRUE | J6: Lost | K6: No | O6: 45963 | P6: =TRUE() -> TRUE | Q6: 669.1
A7: LEAD00006 | B7: 45748 | C7: 45748 | D7: United Kingdom | E7: Direct Sales | F7: Fuel Card | G7: SME | H7: REP004 | I7: =TRUE() -> TRUE | J7: Lost | K7: Yes | L7: 45752 | M7: 45753 | O7: 45765 | P7: =TRUE() -> TRUE | Q7: 784.3
A8: LEAD00007 | B8: 45849 | C8: 45839 | D8: United Kingdom | E8: Digital | F8: Toll Solution | G8: Enterprise | H8: REP005 | I8: =TRUE() -> TRUE | J8: Lost | K8: Yes | L8: 45850 | M8: 45858 | O8: 45872 | P8: =TRUE() -> TRUE | Q8: 5511.46
A9: LEAD00008 | B9: 45826 | C9: 45809 | D9: Germany | E9: Telesales | F9: Fuel Card | G9: Mid-Market | H9: REP001 | I9: =TRUE() -> TRUE | J9: Lost | K9: Yes | L9: 45829 | M9: 45837 | O9: 45856 | P9: =TRUE() -> TRUE | Q9: 2834.62
A10: LEAD00009 | B10: 45783 | C10: 45778 | D10: United Kingdom | E10: Telesales | F10: Toll Solution | G10: SME | H10: REP004 | I10: =TRUE() -> TRUE | J10: Lost | K10: No | O10: 45794 | P10: =TRUE() -> TRUE | Q10: 488.24
A11: LEAD00010 | B11: 46000 | C11: 45992 | D11: United Kingdom | E11: Referral | F11: Toll Solution | G11: Enterprise | H11: REP006 | I11: =TRUE() -> TRUE | J11: Won | K11: Yes | L11: 46004 | M11: 46007 | N11: 46023 | P11: =TRUE() -> TRUE | Q11: 6898.05
A12: LEAD00011 | B12: 45858 | C12: 45839 | D12: United Kingdom | E12: Digital | F12: Toll Solution | G12: SME | H12: REP006 | I12: =TRUE() -> TRUE | J12: Lost | K12: Yes | L12: 45868 | O12: 45893 | P12: =TRUE() -> TRUE | Q12: 696.21
A13: LEAD00012 | B13: 45807 | C13: 45778 | D13: Netherlands | E13: Referral | F13: Fuel Card | G13: SME | H13: REP009 | I13: =TRUE() -> TRUE | J13: Won | K13: Yes | L13: 45817 | M13: 45831 | N13: 45842 | P13: =TRUE() -> TRUE | Q13: 732.38
A14: LEAD00013 | B14: 46013 | C14: 45992 | D14: Netherlands | E14: Direct Sales | F14: Fuel Card | G14: Mid-Market | H14: REP008 | I14: =TRUE() -> TRUE | J14: Opportunity | K14: Yes | L14: 46016 | M14: 46028 | P14: =TRUE() -> TRUE | Q14: 3026.95
A15: LEAD00014 | B15: 46008 | C15: 45992 | D15: France | E15: Telesales | F15: Toll Solution | G15: Enterprise | H15: REP015 | I15: =TRUE() -> TRUE | J15: Qualified | K15: Yes | L15: 46016 | P15: =TRUE() -> TRUE | Q15: 4150.69
A16: LEAD00015 | B16: 45719 | C16: 45717 | D16: France | E16: Partner | F16: Toll Solution | G16: Mid-Market | H16: REP015 | I16: =TRUE() -> TRUE | J16: Won | K16: Yes | L16: 45722 | M16: 45731 | N16: 45759 | P16: =TRUE() -> TRUE | Q16: 1713.23
A17: LEAD00016 | B17: 45779 | C17: 45778 | D17: United Kingdom | E17: Direct Sales | F17: Fuel Card | G17: Mid-Market | H17: REP004 | I17: =TRUE() -> TRUE | J17: Won | K17: Yes | L17: 45783 | M17: 45791 | N17: 45821 | P17: =TRUE() -> TRUE | Q17: 2249.42
A18: LEAD00017 | B18: 45938 | C18: 45931 | D18: Netherlands | E18: Digital | F18: Fuel Card | G18: SME | H18: REP007 | I18: =TRUE() -> TRUE | J18: Lost | K18: No | O18: 45940 | P18: =TRUE() -> TRUE | Q18: 758
A19: LEAD00018 | B19: 45864 | C19: 45839 | D19: United Kingdom | E19: Telesales | F19: Fleet Expense Card | G19: SME | H19: REP005 | I19: =TRUE() -> TRUE | J19: Lost | K19: No | O19: 45874 | P19: =TRUE() -> TRUE | Q19: 606.03
A20: LEAD00019 | B20: 45843 | C20: 45839 | D20: United Kingdom | E20: Direct Sales | F20: EV Charge Card | G20: SME | H20: REP006 | I20: =TRUE() -> TRUE | J20: Lost | K20: Yes | L20: 45851 | M20: 45863 | O20: 45868 | P20: =TRUE() -> TRUE | Q20: 697.01
A21: LEAD00020 | B21: 45843 | C21: 45839 | D21: United Kingdom | E21: Partner | F21: Fuel Card | G21: SME | H21: REP005 | I21: =TRUE() -> TRUE | J21: Lost | K21: Yes | L21: 45849 | M21: 45861 | O21: 45876 | P21: =TRUE() -> TRUE | Q21: 1032.97
A22: LEAD00021 | B22: 46011 | C22: 45992 | D22: Germany | E22: Partner | F22: Fuel Card | G22: Enterprise | H22: REP002 | I22: =TRUE() -> TRUE | J22: New | K22: No | P22: =TRUE() -> TRUE | Q22: 8553.35
A23: LEAD00022 | B23: 45747 | C23: 45717 | D23: Germany | E23: Partner | F23: Fuel Card | G23: Mid-Market | H23: REP003 | I23: =TRUE() -> TRUE | J23: Lost | K23: No | O23: 45767 | P23: =TRUE() -> TRUE | Q23: 2924.3
A24: LEAD00023 | B24: 45691 | C24: 45689 | D24: United Kingdom | E24: Direct Sales | F24: EV Charge Card | G24: Mid-Market | H24: REP004 | I24: =TRUE() -> TRUE | J24: Lost | K24: Yes | L24: 45701 | M24: 45713 | O24: 45724 | P24: =TRUE() -> TRUE | Q24: 1869.87
A25: LEAD00024 | B25: 45694 | C25: 45689 | D25: Netherlands | E25: Digital | F25: Fuel Card | G25: SME | H25: REP009 | I25: =TRUE() -> TRUE | J25: Lost | K25: Yes | L25: 45699 | M25: 45703 | O25: 45736 | P25: =TRUE() -> TRUE | Q25: 902.15
A26: LEAD00025 | B26: 46022 | C26: 45992 | D26: United Kingdom | E26: Direct Sales | F26: EV Charge Card | G26: SME | H26: REP006 | I26: =TRUE() -> TRUE | J26: Won | K26: Yes | L26: 46025 | M26: 46027 | N26: 46043 | P26: =TRUE() -> TRUE | Q26: 670.98
A27: LEAD00026 | B27: 45876 | C27: 45870 | D27: France | E27: Digital | F27: Toll Solution | G27: SME | H27: REP015 | I27: =TRUE() -> TRUE | J27: Lost | K27: No | O27: 45889 | P27: =TRUE() -> TRUE | Q27: 668.86
A28: LEAD00027 | B28: 45667 | C28: 45658 | D28: United Kingdom | E28: Digital | F28: EV Charge Card | G28: Mid-Market | H28: REP004 | I28: =TRUE() -> TRUE | J28: Lost | K28: Yes | L28: 45670 | M28: 45671 | O28: 45677 | P28: =TRUE() -> TRUE | Q28: 1973.56
A29: LEAD00028 | B29: 46008 | C29: 45992 | D29: Netherlands | E29: Direct Sales | F29: Fuel Card | G29: Mid-Market | H29: REP008 | I29: =TRUE() -> TRUE | J29: Qualified | K29: Yes | L29: 46010 | P29: =TRUE() -> TRUE | Q29: 3492.52
A30: LEAD00029 | B30: 45963 | C30: 45962 | D30: United Kingdom | E30: Partner | F30: Toll Solution | G30: SME | H30: REP004 | I30: =TRUE() -> TRUE | J30: Lost | K30: Yes | L30: 45968 | M30: 45973 | O30: 45998 | P30: =TRUE() -> TRUE | Q30: 642.32
A31: LEAD00030 | B31: 45993 | C31: 45992 | D31: Czech Republic | E31: Digital | F31: Fuel Card | G31: SME | H31: REP011 | I31: =TRUE() -> TRUE | J31: Qualified | K31: Yes | L31: 46000 | P31: =TRUE() -> TRUE | Q31: 1099.29
A32: LEAD00031 | B32: 45929 | C32: 45901 | D32: Germany | E32: Partner | F32: Fuel Card | G32: SME | H32: REP001 | I32: =TRUE() -> TRUE | J32: Lost | K32: No | O32: 45948 | P32: =TRUE() -> TRUE | Q32: 911.88
A33: LEAD00032 | B33: 45999 | C33: 45992 | D33: Germany | E33: Digital | F33: Toll Solution | G33: Mid-Market | H33: REP002 | I33: =TRUE() -> TRUE | J33: Opportunity | K33: Yes | L33: 46009 | M33: 46023 | P33: =TRUE() -> TRUE | Q33: 1958.18
A34: LEAD00033 | B34: 45985 | C34: 45962 | D34: United Kingdom | E34: Direct Sales | F34: Fuel Card | G34: SME | H34: REP006 | I34: =TRUE() -> TRUE | J34: Won | K34: Yes | L34: 45995 | M34: 45996 | N34: 46004 | P34: =TRUE() -> TRUE | Q34: 725.29
A35: LEAD00034 | B35: 45882 | C35: 45870 | D35: Czech Republic | E35: Direct Sales | F35: Fuel Card | G35: Mid-Market | H35: REP011 | I35: =TRUE() -> TRUE | J35: Lost | K35: Yes | L35: 45884 | M35: 45898 | O35: 45933 | P35: =TRUE() -> TRUE | Q35: 2842.9
A36: LEAD00035 | B36: 45669 | C36: 45658 | D36: France | E36: Partner | F36: Fuel Card | G36: SME | H36: REP013 | I36: =TRUE() -> TRUE | J36: Won | K36: Yes | L36: 45674 | M36: 45681 | N36: 45700 | P36: =TRUE() -> TRUE | Q36: 1113.11
A37: LEAD00036 | B37: 45715 | C37: 45689 | D37: France | E37: Partner | F37: Fleet Expense Card | G37: SME | H37: REP013 | I37: =TRUE() -> TRUE | J37: Lost | K37: Yes | L37: 45720 | M37: 45734 | O37: 45741 | P37: =TRUE() -> TRUE | Q37: 613.5
A38: LEAD00037 | B38: 45992 | C38: 45992 | D38: France | E38: Direct Sales | F38: Toll Solution | G38: Mid-Market | H38: REP014 | I38: =TRUE() -> TRUE | J38: Opportunity | K38: Yes | L38: 45993 | M38: 46001 | P38: =TRUE() -> TRUE | Q38: 1617.27
A39: LEAD00038 | B39: 45702 | C39: 45689 | D39: Netherlands | E39: Referral | F39: Fuel Card | G39: Mid-Market | H39: REP009 | I39: =TRUE() -> TRUE | J39: Won | K39: Yes | L39: 45710 | M39: 45714 | N39: 45717 | P39: =TRUE() -> TRUE | Q39: 3476.46
A40: LEAD00039 | B40: 45888 | C40: 45870 | D40: Netherlands | E40: Partner | F40: Fuel Card | G40: SME | H40: REP009 | I40: =TRUE() -> TRUE | J40: Lost | K40: No | O40: 45891 | P40: =TRUE() -> TRUE | Q40: 618.24
...

Sheet Clean_Customers
A1: Customer_ID | B1: Lead_ID | C1: Lead_Match_Valid | D1: Won_Date | E1: Activation_Date | F1: Activation_Duration_Valid | G1: Activated_Flag | H1: Market | I1: Product | J1: Channel | K1: Sales_Rep_ID | L1: Customer_Segment | M1: Customer_Status | N1: Customer_Status_Clean | O1: Churn_Date | P1: Expected_Monthly_Revenue_EUR | Q1: Days_To_Activation
A2: CUST00001 | B2: LEAD00010 | C2: =TRUE() -> TRUE | D2: 46023 | E2: 46065 | F2: =TRUE() -> TRUE | G2: =TRUE() -> TRUE | H2: United Kingdom | I2: Toll Solution | J2: Referral | K2: REP006 | L2: Enterprise | M2: Active | N2: Active | P2: 6898.05 | Q2: =IF(G2=TRUE(),E2-D2,"") -> 42
A3: CUST00002 | B3: LEAD00012 | C3: =TRUE() -> TRUE | D3: 45842 | E3: 45876 | F3: =TRUE() -> TRUE | G3: =TRUE() -> TRUE | H3: Netherlands | I3: Fuel Card | J3: Referral | K3: REP009 | L3: SME | M3: Active | N3: Active | P3: 732.38 | Q3: =IF(G3=TRUE(),E3-D3,"") -> 34
A4: CUST00003 | B4: LEAD00015 | C4: =TRUE() -> TRUE | D4: 45759 | E4: 45776 | F4: =TRUE() -> TRUE | G4: =TRUE() -> TRUE | H4: France | I4: Toll Solution | J4: Partner | K4: REP015 | L4: Mid-Market | M4: Active | N4: Active | P4: 1713.23 | Q4: =IF(G4=TRUE(),E4-D4,"") -> 17
A5: CUST00004 | B5: LEAD00016 | C5: =TRUE() -> TRUE | D5: 45821 | E5: 45850 | F5: =TRUE() -> TRUE | G5: =TRUE() -> TRUE | H5: United Kingdom | I5: Fuel Card | J5: Direct Sales | K5: REP004 | L5: Mid-Market | M5: Churned | N5: Churned | O5: 45941 | P5: 2249.42 | Q5: =IF(G5=TRUE(),E5-D5,"") -> 29
A6: CUST00005 | B6: LEAD00025 | C6: =TRUE() -> TRUE | D6: 46043 | E6: 46057 | F6: =TRUE() -> TRUE | G6: =TRUE() -> TRUE | H6: United Kingdom | I6: EV Charge Card | J6: Direct Sales | K6: REP006 | L6: SME | M6: Active | N6: Active | P6: 670.98 | Q6: =IF(G6=TRUE(),E6-D6,"") -> 14
A7: CUST00006 | B7: LEAD99999 | C7: =FALSE() -> FALSE | D7: 46004 | E7: 46035 | F7: =TRUE() -> TRUE | G7: =TRUE() -> TRUE | H7: United Kingdom | I7: Fuel Card | J7: Direct Sales | K7: REP006 | L7: SME | M7: Active | N7: Active | P7: 725.29 | Q7: =IF(G7=TRUE(),E7-D7,"") -> 31
A8: CUST00007 | B8: LEAD00035 | C8: =TRUE() -> TRUE | D8: 45700 | E8: 45711 | F8: =TRUE() -> TRUE | G8: =TRUE() -> TRUE | H8: France | I8: Fuel Card | J8: Partner | K8: REP013 | L8: SME | M8: Active | N8: Active | P8: 1113.11 | Q8: =IF(G8=TRUE(),E8-D8,"") -> 11
A9: CUST00008 | B9: LEAD00038 | C9: =TRUE() -> TRUE | D9: 45717 | F9: =TRUE() -> TRUE | G9: =FALSE() -> FALSE | H9: Netherlands | I9: Fuel Card | J9: Referral | K9: REP009 | L9: Mid-Market | M9: Not Activated | N9: Not Activated | P9: 3476.46 | Q9: =IF(G9=TRUE(),E9-D9,"")
A10: CUST00009 | B10: LEAD00041 | C10: =TRUE() -> TRUE | D10: 45741 | E10: 45778 | F10: =TRUE() -> TRUE | G10: =TRUE() -> TRUE | H10: United Kingdom | I10: EV Charge Card | J10: Referral | K10: REP006 | L10: Enterprise | M10: Active | N10: Active | P10: 5529.48 | Q10: =IF(G10=TRUE(),E10-D10,"") -> 37
A11: CUST00010 | B11: LEAD00046 | C11: =TRUE() -> TRUE | D11: 45952 | E11: 45983 | F11: =TRUE() -> TRUE | G11: =TRUE() -> TRUE | H11: United Kingdom | I11: Fuel Card | J11: Direct Sales | K11: REP004 | L11: SME | M11: Active | N11: Active | P11: 823.17 | Q11: =IF(G11=TRUE(),E11-D11,"") -> 31
A12: CUST00011 | B12: LEAD00049 | C12: =TRUE() -> TRUE | D12: 45923 | E12: 45929 | F12: =TRUE() -> TRUE | G12: =TRUE() -> TRUE | H12: Germany | I12: Toll Solution | J12: Referral | K12: REP002 | L12: SME | M12: Active | N12: Active | P12: 682.3 | Q12: =IF(G12=TRUE(),E12-D12,"") -> 6
A13: CUST00012 | B13: LEAD00058 | C13: =TRUE() -> TRUE | D13: 45757 | E13: 45798 | F13: =TRUE() -> TRUE | G13: =TRUE() -> TRUE | H13: United Kingdom | I13: EV Charge Card | J13: Partner | K13: REP006 | L13: SME | M13: Active | N13: Active | P13: 710.84 | Q13: =IF(G13=TRUE(),E13-D13,"") -> 41
A14: CUST00013 | B14: LEAD00064 | C14: =TRUE() -> TRUE | D14: 46021 | E14: 46019 | F14: =FALSE() -> FALSE | G14: =FALSE() -> FALSE | H14: United Kingdom | I14: EV Charge Card | J14: Telesales | K14: REP006 | L14: SME | M14: Active | N14: Active | P14: 565.82 | Q14: =IF(G14=TRUE(),E14-D14,"")
A15: CUST00014 | B15: LEAD00069 | C15: =TRUE() -> TRUE | D15: 45828 | E15: 45854 | F15: =TRUE() -> TRUE | G15: =TRUE() -> TRUE | H15: Germany | I15: Fuel Card | J15: Direct Sales | K15: REP002 | L15: SME | M15: Active | N15: Active | P15: 601.64 | Q15: =IF(G15=TRUE(),E15-D15,"") -> 26
A16: CUST00015 | B16: LEAD00072 | C16: =TRUE() -> TRUE | D16: 45769 | E16: 45796 | F16: =TRUE() -> TRUE | G16: =TRUE() -> TRUE | H16: United Kingdom | I16: Fleet Expense Card | J16: Direct Sales | K16: REP006 | L16: SME | M16: Active | N16: Active | P16: 594.28 | Q16: =IF(G16=TRUE(),E16-D16,"") -> 27
A17: CUST00016 | B17: LEAD00074 | C17: =TRUE() -> TRUE | D17: 45989 | E17: 45991 | F17: =TRUE() -> TRUE | G17: =TRUE() -> TRUE | H17: Germany | I17: EV Charge Card | J17: Digital | K17: REP001 | L17: SME | M17: Active | N17: Active | P17: 755.27 | Q17: =IF(G17=TRUE(),E17-D17,"") -> 2
A18: CUST00017 | B18: LEAD00075 | C18: =TRUE() -> TRUE | D18: 45824 | E18: 45827 | F18: =TRUE() -> TRUE | G18: =TRUE() -> TRUE | H18: France | I18: Fuel Card | J18: Partner | K18: REP015 | L18: Mid-Market | M18: Active | N18: Active | P18: 2303.13 | Q18: =IF(G18=TRUE(),E18-D18,"") -> 3
A19: CUST00018 | B19: LEAD00081 | C19: =TRUE() -> TRUE | D19: 45879 | E19: 45897 | F19: =TRUE() -> TRUE | G19: =TRUE() -> TRUE | H19: Netherlands | I19: EV Charge Card | J19: Partner | K19: REP009 | L19: Mid-Market | M19: Active | N19: Active | P19: 2363.89 | Q19: =IF(G19=TRUE(),E19-D19,"") -> 18
A20: CUST00019 | B20: LEAD00082 | C20: =TRUE() -> TRUE | D20: 45963 | F20: =TRUE() -> TRUE | G20: =FALSE() -> FALSE | H20: France | I20: Fuel Card | J20: Direct Sales | K20: REP015 | L20: SME | M20: Not Activated | N20: Not Activated | P20: 1129.44 | Q20: =IF(G20=TRUE(),E20-D20,"")
A21: CUST00020 | B21: LEAD00086 | C21: =TRUE() -> TRUE | D21: 45746 | E21: 45793 | F21: =TRUE() -> TRUE | G21: =TRUE() -> TRUE | H21: Germany | I21: Fuel Card | J21: Partner | K21: REP003 | L21: Enterprise | M21: Active | N21: Active | P21: 6878.5 | Q21: =IF(G21=TRUE(),E21-D21,"") -> 47
A22: CUST00021 | B22: LEAD99999 | C22: =FALSE() -> FALSE | D22: 45740 | E22: 45796 | F22: =TRUE() -> TRUE | G22: =TRUE() -> TRUE | H22: Germany | I22: Fuel Card | J22: Partner | K22: REP003 | L22: Mid-Market | M22: Active | N22: Active | P22: 2560.47 | Q22: =IF(G22=TRUE(),E22-D22,"") -> 56
A23: CUST00022 | B23: LEAD00089 | C23: =TRUE() -> TRUE | D23: 45821 | E23: 45837 | F23: =TRUE() -> TRUE | G23: =TRUE() -> TRUE | H23: Netherlands | I23: Fuel Card | J23: Partner | K23: REP008 | L23: Enterprise | M23: Active | N23: Active | P23: 8785.69 | Q23: =IF(G23=TRUE(),E23-D23,"") -> 16
A24: CUST00023 | B24: LEAD00090 | C24: =TRUE() -> TRUE | D24: 46000 | E24: 46043 | F24: =TRUE() -> TRUE | G24: =TRUE() -> TRUE | H24: France | I24: Fuel Card | J24: Direct Sales | K24: REP013 | L24: Mid-Market | M24: Active | N24: Active | P24: 2533.19 | Q24: =IF(G24=TRUE(),E24-D24,"") -> 43
A25: CUST00024 | B25: LEAD00092 | C25: =TRUE() -> TRUE | D25: 45750 | E25: 45760 | F25: =TRUE() -> TRUE | G25: =TRUE() -> TRUE | H25: Netherlands | I25: Fleet Expense Card | J25: Direct Sales | K25: REP008 | L25: Unclassified | M25: Active | N25: Active | P25: 585.85 | Q25: =IF(G25=TRUE(),E25-D25,"") -> 10
A26: CUST00025 | B26: LEAD00104 | C26: =TRUE() -> TRUE | D26: 45761 | E26: 45778 | F26: =TRUE() -> TRUE | G26: =TRUE() -> TRUE | H26: France | I26: Toll Solution | J26: Partner | K26: REP015 | L26: Mid-Market | M26: Active | N26: Active | P26: 2145.83 | Q26: =IF(G26=TRUE(),E26-D26,"") -> 17
A27: CUST00026 | B27: LEAD00106 | C27: =TRUE() -> TRUE | D27: 45869 | E27: 45883 | F27: =TRUE() -> TRUE | G27: =TRUE() -> TRUE | H27: Netherlands | I27: Fleet Expense Card | J27: Partner | K27: REP008 | L27: SME | M27: Active | N27: Active | P27: 921.4 | Q27: =IF(G27=TRUE(),E27-D27,"") -> 14
A28: CUST00027 | B28: LEAD00108 | C28: =TRUE() -> TRUE | D28: 45985 | E28: 46029 | F28: =TRUE() -> TRUE | G28: =TRUE() -> TRUE | H28: Czech Republic | I28: Fleet Expense Card | J28: Direct Sales | K28: REP012 | L28: Mid-Market | M28: Active | N28: Active | P28: 2768.87 | Q28: =IF(G28=TRUE(),E28-D28,"") -> 44
A29: CUST00028 | B29: LEAD00111 | C29: =TRUE() -> TRUE | D29: 45891 | E29: 45918 | F29: =TRUE() -> TRUE | G29: =TRUE() -> TRUE | H29: France | I29: Fuel Card | J29: Direct Sales | K29: REP015 | L29: Mid-Market | M29: Active | N29: Active | P29: 2084.05 | Q29: =IF(G29=TRUE(),E29-D29,"") -> 27
A30: CUST00029 | B30: LEAD00112 | C30: =TRUE() -> TRUE | D30: 45879 | E30: 45923 | F30: =TRUE() -> TRUE | G30: =TRUE() -> TRUE | H30: France | I30: Fuel Card | J30: Direct Sales | K30: REP015 | L30: Mid-Market | M30: Active | N30: Active | P30: 2684.85 | Q30: =IF(G30=TRUE(),E30-D30,"") -> 44
A31: CUST00030 | B31: LEAD00113 | C31: =TRUE() -> TRUE | D31: 45801 | E31: 45814 | F31: =TRUE() -> TRUE | G31: =TRUE() -> TRUE | H31: Netherlands | I31: Fuel Card | J31: Referral | K31: REP008 | L31: Unclassified | M31: Churned | N31: Churned | O31: 45889 | P31: 10631.28 | Q31: =IF(G31=TRUE(),E31-D31,"") -> 13
A32: CUST00031 | B32: LEAD00115 | C32: =TRUE() -> TRUE | D32: 45936 | E32: 45981 | F32: =TRUE() -> TRUE | G32: =TRUE() -> TRUE | H32: United Kingdom | I32: EV Charge Card | J32: Referral | K32: REP004 | L32: SME | M32: Active | N32: Active | P32: 843.9 | Q32: =IF(G32=TRUE(),E32-D32,"") -> 45
A33: CUST00032 | B33: LEAD00125 | C33: =TRUE() -> TRUE | D33: 45763 | E33: 45767 | F33: =TRUE() -> TRUE | G33: =TRUE() -> TRUE | H33: Germany | I33: Fuel Card | J33: Telesales | K33: REP001 | L33: SME | M33: Active | N33: Active | P33: 1012.09 | Q33: =IF(G33=TRUE(),E33-D33,"") -> 4
A34: CUST00033 | B34: LEAD00126 | C34: =TRUE() -> TRUE | D34: 45941 | E34: 46007 | F34: =TRUE() -> TRUE | G34: =TRUE() -> TRUE | H34: Germany | I34: Fuel Card | J34: Partner | K34: REP003 | L34: Enterprise | M34: Active | N34: Active | P34: 10550.44 | Q34: =IF(G34=TRUE(),E34-D34,"") -> 66
A35: CUST00034 | B35: LEAD00129 | C35: =TRUE() -> TRUE | D35: 45878 | E35: 45906 | F35: =TRUE() -> TRUE | G35: =TRUE() -> TRUE | H35: Czech Republic | I35: Fuel Card | J35: Direct Sales | K35: REP010 | L35: SME | M35: Active | N35: Active | P35: 994.66 | Q35: =IF(G35=TRUE(),E35-D35,"") -> 28
A36: CUST00035 | B36: LEAD00132 | C36: =TRUE() -> TRUE | D36: 45741 | E36: 45786 | F36: =TRUE() -> TRUE | G36: =TRUE() -> TRUE | H36: France | I36: Toll Solution | J36: Direct Sales | K36: REP014 | L36: Mid-Market | M36: Active | N36: Active | P36: 1434.56 | Q36: =IF(G36=TRUE(),E36-D36,"") -> 45
A37: CUST00036 | B37: LEAD00135 | C37: =TRUE() -> TRUE | D37: 45777 | E37: 45814 | F37: =TRUE() -> TRUE | G37: =TRUE() -> TRUE | H37: Czech Republic | I37: Fuel Card | J37: Referral | K37: REP011 | L37: Enterprise | M37: Active | N37: Active | P37: 6669.82 | Q37: =IF(G37=TRUE(),E37-D37,"") -> 37
A38: CUST00037 | B38: LEAD00136 | C38: =TRUE() -> TRUE | D38: 45977 | E38: 46015 | F38: =TRUE() -> TRUE | G38: =TRUE() -> TRUE | H38: France | I38: Fuel Card | J38: Direct Sales | K38: REP014 | L38: Mid-Market | M38: Active | N38: Active | P38: 3313.31 | Q38: =IF(G38=TRUE(),E38-D38,"") -> 38
A39: CUST00038 | B39: LEAD00141 | C39: =TRUE() -> TRUE | D39: 45828 | E39: 45838 | F39: =TRUE() -> TRUE | G39: =TRUE() -> TRUE | H39: United Kingdom | I39: EV Charge Card | J39: Direct Sales | K39: REP006 | L39: SME | M39: Active | N39: Active | P39: 879.21 | Q39: =IF(G39=TRUE(),E39-D39,"") -> 10
A40: CUST00039 | B40: LEAD00142 | C40: =TRUE() -> TRUE | D40: 45751 | E40: 45774 | F40: =TRUE() -> TRUE | G40: =TRUE() -> TRUE | H40: Netherlands | I40: Fuel Card | J40: Direct Sales | K40: REP007 | L40: SME | M40: Active | N40: Active | P40: 1001.56 | Q40: =IF(G40=TRUE(),E40-D40,"") -> 23
...

Sheet Clean_Transactions
A1: Transaction_ID | B1: Customer_ID | C1: Customer_Match_Valid | D1: Transaction_Date | E1: Transaction_Month | F1: Transaction_Type | G1: Gross_Value_EUR | H1: Revenue_EUR | I1: Revenue_Valid | J1: Transaction_Status | K1: Revenue_Usable | L1: Market | M1: Rep_ID_via_Customer | N1: Channel_via_Customer | O1: Product_via_Customer | P1: Segment_via_Customer
A2: TXN0000001 | B2: CUST00002 | C2: =TRUE() -> TRUE | D2: 45887 | E2: 45870 | F2: Fuel | G2: 3084.52 | H2: 71.6 | I2: =TRUE() -> TRUE | J2: Completed | K2: 71.6 | L2: Netherlands | M2: =IFERROR(INDEX(T_CleanCustomers[Sales_Rep_ID],MATCH(B2,T_CleanCustomers[Customer_ID],0)),"Unmatched") -> REP009 | N2: =IFERROR(INDEX(T_CleanCustomers[Channel],MATCH(B2,T_CleanCustomers[Customer_ID],0)),"Unmatched") -> Referral | O2: =IFERROR(INDEX(T_CleanCustomers[Product],MATCH(B2,T_CleanCustomers[Customer_ID],0)),"Unmatched") -> Fuel Card | P2: =IFERROR(INDEX(T_CleanCustomers[Customer_Segment],MATCH(B2,T_CleanCustomers[Customer_ID],0)),"Unmatched") -> SME
A3: TXN0000002 | B3: CUST00002 | C3: =TRUE() -> TRUE | D3: 45876 | E3: 45870 | F3: Fuel | G3: 4576.08 | H3: 105.35 | I3: =TRUE() -> TRUE | J3: Completed | K3: 105.35 | L3: Netherlands | M3: =IFERROR(INDEX(T_CleanCustomers[Sales_Rep_ID],MATCH(B3,T_CleanCustomers[Customer_ID],0)),"Unmatched") -> REP009 | N3: =IFERROR(INDEX(T_CleanCustomers[Channel],MATCH(B3,T_CleanCustomers[Customer_ID],0)),"Unmatched") -> Referral | O3: =IFERROR(INDEX(T_CleanCustomers[Product],MATCH(B3,T_CleanCustomers[Customer_ID],0)),"Unmatched") -> Fuel Card | P3: =IFERROR(INDEX(T_CleanCustomers[Customer_Segment],MATCH(B3,T_CleanCustomers[Customer_ID],0)),"Unmatched") -> SME
A4: TXN0000003 | B4: CUST00002 | C4: =TRUE() -> TRUE | D4: 45917 | E4: 45901 | F4: Fuel | G4: 4134.54 | H4: 116.94 | I4: =TRUE() -> TRUE | J4: Completed | K4: 116.94 | L4: Netherlands | M4: =IFERROR(INDEX(T_CleanCustomers[Sales_Rep_ID],MATCH(B4,T_CleanCustomers[Customer_ID],0)),"Unmatched") -> REP009 | N4: =IFERROR(INDEX(T_CleanCustomers[Channel],MATCH(B4,T_CleanCustomers[Customer_ID],0)),"Unmatched") -> Referral | O4: =IFERROR(INDEX(T_CleanCustomers[Product],MATCH(B4,T_CleanCustomers[Customer_ID],0)),"Unmatched") -> Fuel Card | P4: =IFERROR(INDEX(T_CleanCustomers[Customer_Segment],MATCH(B4,T_CleanCustomers[Customer_ID],0)),"Unmatched") -> SME
A5: TXN0000004 | B5: CUST00002 | C5: =TRUE() -> TRUE | D5: 45913 | E5: 45901 | F5: Fuel | G5: 3812.91 | H5: 84.68 | I5: =TRUE() -> TRUE | J5: Completed | K5: 84.68 | L5: Netherlands | M5: =IFERROR(INDEX(T_CleanCustomers[Sales_Rep_ID],MATCH(B5,T_CleanCustomers[Customer_ID],0)),"Unmatched") -> REP009 | N5: =IFERROR(INDEX(T_CleanCustomers[Channel],MATCH(B5,T_CleanCustomers[Customer_ID],0)),"Unmatched") -> Referral | O5: =IFERROR(INDEX(T_CleanCustomers[Product],MATCH(B5,T_CleanCustomers[Customer_ID],0)),"Unmatched") -> Fuel Card | P5: =IFERROR(INDEX(T_CleanCustomers[Customer_Segment],MATCH(B5,T_CleanCustomers[Customer_ID],0)),"Unmatched") -> SME
A6: TXN0000005 | B6: CUST00002 | C6: =TRUE() -> TRUE | D6: 45946 | E6: 45931 | F6: Fuel | G6: 4003.93 | H6: 100.39 | I6: =TRUE() -> TRUE | J6: Completed | K6: 100.39 | L6: Netherlands | M6: =IFERROR(INDEX(T_CleanCustomers[Sales_Rep_ID],MATCH(B6,T_CleanCustomers[Customer_ID],0)),"Unmatched") -> REP009 | N6: =IFERROR(INDEX(T_CleanCustomers[Channel],MATCH(B6,T_CleanCustomers[Customer_ID],0)),"Unmatched") -> Referral | O6: =IFERROR(INDEX(T_CleanCustomers[Product],MATCH(B6,T_CleanCustomers[Customer_ID],0)),"Unmatched") -> Fuel Card | P6: =IFERROR(INDEX(T_CleanCustomers[Customer_Segment],MATCH(B6,T_CleanCustomers[Customer_ID],0)),"Unmatched") -> SME
A7: TXN0000006 | B7: CUST00002 | C7: =TRUE() -> TRUE | D7: 45942 | E7: 45931 | F7: Fuel | G7: 3911.11 | H7: 106.16 | I7: =TRUE() -> TRUE | J7: Completed | K7: 106.16 | L7: Netherlands | M7: =IFERROR(INDEX(T_CleanCustomers[Sales_Rep_ID],MATCH(B7,T_CleanCustomers[Customer_ID],0)),"Unmatched") -> REP009 | N7: =IFERROR(INDEX(T_CleanCustomers[Channel],MATCH(B7,T_CleanCustomers[Customer_ID],0)),"Unmatched") -> Referral | O7: =IFERROR(INDEX(T_CleanCustomers[Product],MATCH(B7,T_CleanCustomers[Customer_ID],0)),"Unmatched") -> Fuel Card | P7: =IFERROR(INDEX(T_CleanCustomers[Customer_Segment],MATCH(B7,T_CleanCustomers[Customer_ID],0)),"Unmatched") -> SME
A8: TXN0000007 | B8: CUST00002 | C8: =TRUE() -> TRUE | D8: 45948 | E8: 45931 | F8: Fuel | G8: 4879.35 | H8: 130.23 | I8: =TRUE() -> TRUE | J8: Completed | K8: 130.23 | L8: Netherlands | M8: =IFERROR(INDEX(T_CleanCustomers[Sales_Rep_ID],MATCH(B8,T_CleanCustomers[Customer_ID],0)),"Unmatched") -> REP009 | N8: =IFERROR(INDEX(T_CleanCustomers[Channel],MATCH(B8,T_CleanCustomers[Customer_ID],0)),"Unmatched") -> Referral | O8: =IFERROR(INDEX(T_CleanCustomers[Product],MATCH(B8,T_CleanCustomers[Customer_ID],0)),"Unmatched") -> Fuel Card | P8: =IFERROR(INDEX(T_CleanCustomers[Customer_Segment],MATCH(B8,T_CleanCustomers[Customer_ID],0)),"Unmatched") -> SME
A9: TXN0000008 | B9: CUST00002 | C9: =TRUE() -> TRUE | D9: 45981 | E9: 45962 | F9: Fuel | G9: 3325.52 | H9: 91.85 | I9: =TRUE() -> TRUE | J9: Completed | K9: 91.85 | L9: Netherlands | M9: =IFERROR(INDEX(T_CleanCustomers[Sales_Rep_ID],MATCH(B9,T_CleanCustomers[Customer_ID],0)),"Unmatched") -> REP009 | N9: =IFERROR(INDEX(T_CleanCustomers[Channel],MATCH(B9,T_CleanCustomers[Customer_ID],0)),"Unmatched") -> Referral | O9: =IFERROR(INDEX(T_CleanCustomers[Product],MATCH(B9,T_CleanCustomers[Customer_ID],0)),"Unmatched") -> Fuel Card | P9: =IFERROR(INDEX(T_CleanCustomers[Customer_Segment],MATCH(B9,T_CleanCustomers[Customer_ID],0)),"Unmatched") -> SME
A10: TXN0000009 | B10: CUST00002 | C10: =TRUE() -> TRUE | D10: 45972 | E10: 45962 | F10: Fuel | G10: 4233.7 | H10: 90.19 | I10: =TRUE() -> TRUE | J10: Completed | K10: 90.19 | L10: Netherlands | M10: =IFERROR(INDEX(T_CleanCustomers[Sales_Rep_ID],MATCH(B10,T_CleanCustomers[Customer_ID],0)),"Unmatched") -> REP009 | N10: =IFERROR(INDEX(T_CleanCustomers[Channel],MATCH(B10,T_CleanCustomers[Customer_ID],0)),"Unmatched") -> Referral | O10: =IFERROR(INDEX(T_CleanCustomers[Product],MATCH(B10,T_CleanCustomers[Customer_ID],0)),"Unmatched") -> Fuel Card | P10: =IFERROR(INDEX(T_CleanCustomers[Customer_Segment],MATCH(B10,T_CleanCustomers[Customer_ID],0)),"Unmatched") -> SME
A11: TXN0000010 | B11: CUST00002 | C11: =TRUE() -> TRUE | D11: 46008 | E11: 45992 | F11: Fuel | G11: 1355.81 | H11: 28.92 | I11: =TRUE() -> TRUE | J11: Completed | K11: 28.92 | L11: Netherlands | M11: =IFERROR(INDEX(T_CleanCustomers[Sales_Rep_ID],MATCH(B11,T_CleanCustomers[Customer_ID],0)),"Unmatched") -> REP009 | N11: =IFERROR(INDEX(T_CleanCustomers[Channel],MATCH(B11,T_CleanCustomers[Customer_ID],0)),"Unmatched") -> Referral | O11: =IFERROR(INDEX(T_CleanCustomers[Product],MATCH(B11,T_CleanCustomers[Customer_ID],0)),"Unmatched") -> Fuel Card | P11: =IFERROR(INDEX(T_CleanCustomers[Customer_Segment],MATCH(B11,T_CleanCustomers[Customer_ID],0)),"Unmatched") -> SME
A12: TXN0000011 | B12: CUST00002 | C12: =TRUE() -> TRUE | D12: 46007 | E12: 45992 | F12: Fuel | G12: 3327.6 | H12: 84.65 | I12: =TRUE() -> TRUE | J12: Completed | K12: 84.65 | L12: Netherlands | M12: =IFERROR(INDEX(T_CleanCustomers[Sales_Rep_ID],MATCH(B12,T_CleanCustomers[Customer_ID],0)),"Unmatched") -> REP009 | N12: =IFERROR(INDEX(T_CleanCustomers[Channel],MATCH(B12,T_CleanCustomers[Customer_ID],0)),"Unmatched") -> Referral | O12: =IFERROR(INDEX(T_CleanCustomers[Product],MATCH(B12,T_CleanCustomers[Customer_ID],0)),"Unmatched") -> Fuel Card | P12: =IFERROR(INDEX(T_CleanCustomers[Customer_Segment],MATCH(B12,T_CleanCustomers[Customer_ID],0)),"Unmatched") -> SME
A13: TXN0000012 | B13: CUST00003 | C13: =TRUE() -> TRUE | D13: 45776 | E13: 45748 | F13: Toll | G13: 5152.89 | H13: 87.47 | I13: =TRUE() -> TRUE | J13: Completed | K13: 87.47 | L13: France | M13: =IFERROR(INDEX(T_CleanCustomers[Sales_Rep_ID],MATCH(B13,T_CleanCustomers[Customer_ID],0)),"Unmatched") -> REP015 | N13: =IFERROR(INDEX(T_CleanCustomers[Channel],MATCH(B13,T_CleanCustomers[Customer_ID],0)),"Unmatched") -> Partner | O13: =IFERROR(INDEX(T_CleanCustomers[Product],MATCH(B13,T_CleanCustomers[Customer_ID],0)),"Unmatched") -> Toll Solution | P13: =IFERROR(INDEX(T_CleanCustomers[Customer_Segment],MATCH(B13,T_CleanCustomers[Customer_ID],0)),"Unmatched") -> Mid-Market
... A74: TXN0000073 | B74: CUST00009 | C74: =TRUE() -> TRUE | D74: 45995 | E74: 45992 | F74: EV Charging | G74: 50472.73 | H74: 0 | I74: =TRUE() -> TRUE | J74: Cancelled | K74: 0 | L74: United Kingdom | M74: =IFERROR(INDEX(T_CleanCustomers[Sales_Rep_ID],MATCH(B74,T_CleanCustomers[Customer_ID],0)),"Unmatched") -> REP006 | N74: =IFERROR(INDEX(T_CleanCustomers[Channel],MATCH(B74,T_CleanCustomers[Customer_ID],0)),"Unmatched") -> Referral | O74: =IFERROR(INDEX(T_CleanCustomers[Product],MATCH(B74,T_CleanCustomers[Customer_ID],0)),"Unmatched") -> EV Charge Card | P74: =IFERROR(INDEX(T_CleanCustomers[Customer_Segment],MATCH(B74,T_CleanCustomers[Customer_ID],0)),"Unmatched") -> Enterprise
A75: TXN0000074 | B75: CUST99999 | C75: =FALSE() -> FALSE | D75: 45991 | E75: 45962 | F75: Fuel | G75: 4720.4 | H75: 125.85 | I75: =TRUE() -> TRUE | J75: Completed | K75: 0 | L75: United Kingdom | M75: =IFERROR(INDEX(T_CleanCustomers[Sales_Rep_ID],MATCH(B75,T_CleanCustomers[Customer_ID],0)),"Unmatched") -> Unmatched | N75: =IFERROR(INDEX(T_CleanCustomers[Channel],MATCH(B75,T_CleanCustomers[Customer_ID],0)),"Unmatched") -> Unmatched | O75: =IFERROR(INDEX(T_CleanCustomers[Product],MATCH(B75,T_CleanCustomers[Customer_ID],0)),"Unmatched") -> Unmatched | P75: =IFERROR(INDEX(T_CleanCustomers[Customer_Segment],MATCH(B75,T_CleanCustomers[Customer_ID],0)),"Unmatched") -> Unmatched
A76: TXN0000075 | B76: CUST00010 | C76: =TRUE() -> TRUE | D76: 45989 | E76: 45962 | F76: Fuel | G76: 4472.06 | H76: 102.34 | I76: =TRUE() -> TRUE | J76: Completed | K76: 102.34 | L76: United Kingdom | M76: =IFERROR(INDEX(T_CleanCustomers[Sales_Rep_ID],MATCH(B76,T_CleanCustomers[Customer_ID],0)),"Unmatched") -> REP004 | N76: =IFERROR(INDEX(T_CleanCustomers[Channel],MATCH(B76,T_CleanCustomers[Customer_ID],0)),"Unmatched") -> Direct Sales | O76: =IFERROR(INDEX(T_CleanCustomers[Product],MATCH(B76,T_CleanCustomers[Customer_ID],0)),"Unmatched") -> Fuel Card | P76: =IFERROR(INDEX(T_CleanCustomers[Customer_Segment],MATCH(B76,T_CleanCustomers[Customer_ID],0)),"Unmatched") -> SME
A77: TXN0000076 | B77: CUST00010 | C77: =TRUE() -> TRUE | D77: 46004 | E77: 45992 | F77: Fuel | G77: 2438.67 | H77: 65.5 | I77: =TRUE() -> TRUE | J77: Completed | K77: 65.5 | L77: United Kingdom | M77: =IFERROR(INDEX(T_CleanCustomers[Sales_Rep_ID],MATCH(B77,T_CleanCustomers[Customer_ID],0)),"Unmatched") -> REP004 | N77: =IFERROR(INDEX(T_CleanCustomers[Channel],MATCH(B77,T_CleanCustomers[Customer_ID],0)),"Unmatched") -> Direct Sales | O77: =IFERROR(INDEX(T_CleanCustomers[Product],MATCH(B77,T_CleanCustomers[Customer_ID],0)),"Unmatched") -> Fuel Card | P77: =IFERROR(INDEX(T_CleanCustomers[Customer_Segment],MATCH(B77,T_CleanCustomers[Customer_ID],0)),"Unmatched") -> SME
A78: TXN0000077 | B78: CUST00010 | C78: =TRUE() -> TRUE | D78: 46020 | E78: 45992 | F78: Fuel | G78: 2855.68 | H78: 80.55 | I78: =TRUE() -> TRUE | J78: Completed | K78: 80.55 | L78: United Kingdom | M78: =IFERROR(INDEX(T_CleanCustomers[Sales_Rep_ID],MATCH(B78,T_CleanCustomers[Customer_ID],0)),"Unmatched") -> REP004 | N78: =IFERROR(INDEX(T_CleanCustomers[Channel],MATCH(B78,T_CleanCustomers[Customer_ID],0)),"Unmatched") -> Direct Sales | O78: =IFERROR(INDEX(T_CleanCustomers[Product],MATCH(B78,T_CleanCustomers[Customer_ID],0)),"Unmatched") -> Fuel Card | P78: =IFERROR(INDEX(T_CleanCustomers[Customer_Segment],MATCH(B78,T_CleanCustomers[Customer_ID],0)),"Unmatched") -> SME
A79: TXN0000078 | B79: CUST00010 | C79: =TRUE() -> TRUE | D79: 45995 | E79: 45992 | F79: Fuel | G79: 3865.09 | H79: 102.64 | I79: =TRUE() -> TRUE | J79: Completed | K79: 102.64 | L79: United Kingdom | M79: =IFERROR(INDEX(T_CleanCustomers[Sales_Rep_ID],MATCH(B79,T_CleanCustomers[Customer_ID],0)),"Unmatched") -> REP004 | N79: =IFERROR(INDEX(T_CleanCustomers[Channel],MATCH(B79,T_CleanCustomers[Customer_ID],0)),"Unmatched") -> Direct Sales | O79: =IFERROR(INDEX(T_CleanCustomers[Product],MATCH(B79,T_CleanCustomers[Customer_ID],0)),"Unmatched") -> Fuel Card | P79: =IFERROR(INDEX(T_CleanCustomers[Customer_Segment],MATCH(B79,T_CleanCustomers[Customer_ID],0)),"Unmatched") -> SME
A80: TXN0000079 | B80: CUST00011 | C80: =TRUE() -> TRUE | D80: 45930 | E80: 45901 | F80: Toll | G80: 1275.28 | H80: 21.3 | I80: =TRUE() -> TRUE | J80: Completed | K80: 21.3 | L80: Germany | M80: =IFERROR(INDEX(T_CleanCustomers[Sales_Rep_ID],MATCH(B80,T_CleanCustomers[Customer_ID],0)),"Unmatched") -> REP002 | N80: =IFERROR(INDEX(T_CleanCustomers[Channel],MATCH(B80,T_CleanCustomers[Customer_ID],0)),"Unmatched") -> Referral | O80: =IFERROR(INDEX(T_CleanCustomers[Product],MATCH(B80,T_CleanCustomers[Customer_ID],0)),"Unmatched") -> Toll Solution | P80: =IFERROR(INDEX(T_CleanCustomers[Customer_Segment],MATCH(B80,T_CleanCustomers[Customer_ID],0)),"Unmatched") -> SME
A81: TXN0000080 | B81: CUST00011 | C81: =TRUE() -> TRUE | D81: 45930 | E81: 45901 | F81: Toll | G81: 4686.72 | H81: 94.97 | I81: =TRUE() -> TRUE | J81: Completed | K81: 94.97 | L81: Germany | M81: =IFERROR(INDEX(T_CleanCustomers[Sales_Rep_ID],MATCH(B81,T_CleanCustomers[Customer_ID],0)),"Unmatched") -> REP002 | N81: =IFERROR(INDEX(T_CleanCustomers[Channel],MATCH(B81,T_CleanCustomers[Customer_ID],0)),"Unmatched") -> Referral | O81: =IFERROR(INDEX(T_CleanCustomers[Product],MATCH(B81,T_CleanCustomers[Customer_ID],0)),"Unmatched") -> Toll Solution | P81: =IFERROR(INDEX(T_CleanCustomers[Customer_Segment],MATCH(B81,T_CleanCustomers[Customer_ID],0)),"Unmatched") -> SME
A82: TXN0000081 | B82: CUST00011 | C82: =TRUE() -> TRUE | D82: 45944 | E82: 45931 | F82: Toll | G82: 4479.88 | H82: 91.7 | I82: =TRUE() -> TRUE | J82: Completed | K82: 91.7 | L82: Germany | M82: =IFERROR(INDEX(T_CleanCustomers[Sales_Rep_ID],MATCH(B82,T_CleanCustomers[Customer_ID],0)),"Unmatched") -> REP002 | N82: =IFERROR(INDEX(T_CleanCustomers[Channel],MATCH(B82,T_CleanCustomers[Customer_ID],0)),"Unmatched") -> Referral | O82: =IFERROR(INDEX(T_CleanCustomers[Product],MATCH(B82,T_CleanCustomers[Customer_ID],0)),"Unmatched") -> Toll Solution | P82: =IFERROR(INDEX(T_CleanCustomers[Customer_Segment],MATCH(B82,T_CleanCustomers[Customer_ID],0)),"Unmatched") -> SME
A83: TXN0000082 | B83: CUST00011 | C83: =TRUE() -> TRUE | D83: 45986 | E83: 45962 | F83: Toll | G83: 4345.71 | H83: 83.17 | I83: =TRUE() -> TRUE | J83: Completed | K83: 83.17 | L83: Germany | M83: =IFERROR(INDEX(T_CleanCustomers[Sales_Rep_ID],MATCH(B83,T_CleanCustomers[Customer_ID],0)),"Unmatched") -> REP002 | N83: =IFERROR(INDEX(T_CleanCustomers[Channel],MATCH(B83,T_CleanCustomers[Customer_ID],0)),"Unmatched") -> Referral | O83: =IFERROR(INDEX(T_CleanCustomers[Product],MATCH(B83,T_CleanCustomers[Customer_ID],0)),"Unmatched") -> Toll Solution | P83: =IFERROR(INDEX(T_CleanCustomers[Customer_Segment],MATCH(B83,T_CleanCustomers[Customer_ID],0)),"Unmatched") -> SME
A84: TXN0000083 | B84: CUST00011 | C84: =TRUE() -> TRUE | D84: 45965 | E84: 45962 | F84: Toll | G84: 4684.22 | H84: 79.09 | I84: =TRUE() -> TRUE | J84: Completed | K84: 79.09 | L84: Germany | M84: =IFERROR(INDEX(T_CleanCustomers[Sales_Rep_ID],MATCH(B84,T_CleanCustomers[Customer_ID],0)),"Unmatched") -> REP002 | N84: =IFERROR(INDEX(T_CleanCustomers[Channel],MATCH(B84,T_CleanCustomers[Customer_ID],0)),"Unmatched") -> Referral | O84: =IFERROR(INDEX(T_CleanCustomers[Product],MATCH(B84,T_CleanCustomers[Customer_ID],0)),"Unmatched") -> Toll Solution | P84: =IFERROR(INDEX(T_CleanCustomers[Customer_Segment],MATCH(B84,T_CleanCustomers[Customer_ID],0)),"Unmatched") -> SME
A85: TXN0000084 | B85: CUST00011 | C85: =TRUE() -> TRUE | D85: 45975 | E85: 45962 | F85: Toll | G85: 4024.54 | H85: 63.78 | I85: =TRUE() -> TRUE | J85: Completed | K85: 63.78 | L85: Germany | M85: =IFERROR(INDEX(T_CleanCustomers[Sales_Rep_ID],MATCH(B85,T_CleanCustomers[Customer_ID],0)),"Unmatched") -> REP002 | N85: =IFERROR(INDEX(T_CleanCustomers[Channel],MATCH(B85,T_CleanCustomers[Customer_ID],0)),"Unmatched") -> Referral | O85: =IFERROR(INDEX(T_CleanCustomers[Product],MATCH(B85,T_CleanCustomers[Customer_ID],0)),"Unmatched") -> Toll Solution | P85: =IFERROR(INDEX(T_CleanCustomers[Customer_Segment],MATCH(B85,T_CleanCustomers[Customer_ID],0)),"Unmatched") -> SME
A86: TXN0000085 | B86: CUST00011 | C86: =TRUE() -> TRUE | D86: 46004 | E86: 45992 | F86: Toll | G86: 1862.09 | H86: 36.29 | I86: =TRUE() -> TRUE | J86: Completed | K86: 36.29 | L86: Germany | M86: =IFERROR(INDEX(T_CleanCustomers[Sales_Rep_ID],MATCH(B86,T_CleanCustomers[Customer_ID],0)),"Unmatched") -> REP002 | N86: =IFERROR(INDEX(T_CleanCustomers[Channel],MATCH(B86,T_CleanCustomers[Customer_ID],0)),"Unmatched") -> Referral | O86: =IFERROR(INDEX(T_CleanCustomers[Product],MATCH(B86,T_CleanCustomers[Customer_ID],0)),"Unmatched") -> Toll Solution | P86: =IFERROR(INDEX(T_CleanCustomers[Customer_Segment],MATCH(B86,T_CleanCustomers[Customer_ID],0)),"Unmatched") -> SME
A87: TXN0000086 | B87: CUST00012 | C87: =TRUE() -> TRUE | D87: 45798 | E87: 45778 | F87: EV Charging | G87: 2790.09 | H87: 0 | I87: =TRUE() -> TRUE | J87: Cancelled | K87: 0 | L87: United Kingdom | M87: =IFERROR(INDEX(T_CleanCustomers[Sales_Rep_ID],MATCH(B87,T_CleanCustomers[Customer_ID],0)),"Unmatched") -> REP006 | N87: =IFERROR(INDEX(T_CleanCustomers[Channel],MATCH(B87,T_CleanCustomers[Customer_ID],0)),"Unmatched") -> Partner | O87: =IFERROR(INDEX(T_CleanCustomers[Product],MATCH(B87,T_CleanCustomers[Customer_ID],0)),"Unmatched") -> EV Charge Card | P87: =IFERROR(INDEX(T_CleanCustomers[Customer_Segment],MATCH(B87,T_CleanCustomers[Customer_ID],0)),"Unmatched") -> SME
... A113: TXN0000112 | B113: CUST00014 | C113: =TRUE() -> TRUE | D113: 46011 | E113: 45992 | F113: Fuel | G113: 4453.61 | H113: 97.27 | I113: =TRUE() -> TRUE | J113: Completed | K113: 97.27 | L113: Germany | M113: =IFERROR(INDEX(T_CleanCustomers[Sales_Rep_ID],MATCH(B113,T_CleanCustomers[Customer_ID],0)),"Unmatched") -> REP002 | N113: =IFERROR(INDEX(T_CleanCustomers[Channel],MATCH(B113,T_CleanCustomers[Customer_ID],0)),"Unmatched") -> Direct Sales | O113: =IFERROR(INDEX(T_CleanCustomers[Product],MATCH(B113,T_CleanCustomers[Customer_ID],0)),"Unmatched") -> Fuel Card | P113: =IFERROR(INDEX(T_CleanCustomers[Customer_Segment],MATCH(B113,T_CleanCustomers[Customer_ID],0)),"Unmatched") -> SME
A114: TXN0000113 | B114: CUST00014 | C114: =TRUE() -> TRUE | D114: 46002 | E114: 45992 | F114: Fuel | G114: 1742.23 | H114: -44.57 | I114: =FALSE() -> FALSE | J114: Completed | K114: 0 | L114: Germany | M114: =IFERROR(INDEX(T_CleanCustomers[Sales_Rep_ID],MATCH(B114,T_CleanCustomers[Customer_ID],0)),"Unmatched") -> REP002 | N114: =IFERROR(INDEX(T_CleanCustomers[Channel],MATCH(B114,T_CleanCustomers[Customer_ID],0)),"Unmatched") -> Direct Sales | O114: =IFERROR(INDEX(T_CleanCustomers[Product],MATCH(B114,T_CleanCustomers[Customer_ID],0)),"Unmatched") -> Fuel Card | P114: =IFERROR(INDEX(T_CleanCustomers[Customer_Segment],MATCH(B114,T_CleanCustomers[Customer_ID],0)),"Unmatched") -> SME
A115: TXN0000114 | B115: CUST00015 | C115: =TRUE() -> TRUE | D115: 45802 | E115: 45778 | F115: Fuel | G115: 4569.18 | H115: 133.17 | I115: =TRUE() -> TRUE | J115: Completed | K115: 133.17 | L115: United Kingdom | M115: =IFERROR(INDEX(T_CleanCustomers[Sales_Rep_ID],MATCH(B115,T_CleanCustomers[Customer_ID],0)),"Unmatched") -> REP006 | N115: =IFERROR(INDEX(T_CleanCustomers[Channel],MATCH(B115,T_CleanCustomers[Customer_ID],0)),"Unmatched") -> Direct Sales | O115: =IFERROR(INDEX(T_CleanCustomers[Product],MATCH(B115,T_CleanCustomers[Customer_ID],0)),"Unmatched") -> Fleet Expense Card | P115: =IFERROR(INDEX(T_CleanCustomers[Customer_Segment],MATCH(B115,T_CleanCustomers[Customer_ID],0)),"Unmatched") -> SME
A116: TXN0000115 | B116: CUST00015 | C116: =TRUE() -> TRUE | D116: 45831 | E116: 45809 | F116: Fuel | G116: 3595.03 | H116: 92.35 | I116: =TRUE() -> TRUE | J116: Completed | K116: 92.35 | L116: United Kingdom | M116: =IFERROR(INDEX(T_CleanCustomers[Sales_Rep_ID],MATCH(B116,T_CleanCustomers[Customer_ID],0)),"Unmatched") -> REP006 | N116: =IFERROR(INDEX(T_CleanCustomers[Channel],MATCH(B116,T_CleanCustomers[Customer_ID],0)),"Unmatched") -> Direct Sales | O116: =IFERROR(INDEX(T_CleanCustomers[Product],MATCH(B116,T_CleanCustomers[Customer_ID],0)),"Unmatched") -> Fleet Expense Card | P116: =IFERROR(INDEX(T_CleanCustomers[Customer_Segment],MATCH(B116,T_CleanCustomers[Customer_ID],0)),"Unmatched") -> SME
A117: TXN0000116 | B117: CUST00015 | C117: =TRUE() -> TRUE | D117: 45851 | E117: 45839 | F117: Parking | G117: 4144.33 | H117: 96.7 | I117: =TRUE() -> TRUE | J117: Completed | K117: 96.7 | L117: United Kingdom | M117: =IFERROR(INDEX(T_CleanCustomers[Sales_Rep_ID],MATCH(B117,T_CleanCustomers[Customer_ID],0)),"Unmatched") -> REP006 | N117: =IFERROR(INDEX(T_CleanCustomers[Channel],MATCH(B117,T_CleanCustomers[Customer_ID],0)),"Unmatched") -> Direct Sales | O117: =IFERROR(INDEX(T_CleanCustomers[Product],MATCH(B117,T_CleanCustomers[Customer_ID],0)),"Unmatched") -> Fleet Expense Card | P117: =IFERROR(INDEX(T_CleanCustomers[Customer_Segment],MATCH(B117,T_CleanCustomers[Customer_ID],0)),"Unmatched") -> SME
A118: TXN0000117 | B118: CUST00015 | C118: =TRUE() -> TRUE | D118: 45848 | E118: 45839 | F118: Lodging | G118: 1896.67 | H118: 57.61 | I118: =TRUE() -> TRUE | J118: Completed | K118: 57.61 | L118: United Kingdom | M118: =IFERROR(INDEX(T_CleanCustomers[Sales_Rep_ID],MATCH(B118,T_CleanCustomers[Customer_ID],0)),"Unmatched") -> REP006 | N118: =IFERROR(INDEX(T_CleanCustomers[Channel],MATCH(B118,T_CleanCustomers[Customer_ID],0)),"Unmatched") -> Direct Sales | O118: =IFERROR(INDEX(T_CleanCustomers[Product],MATCH(B118,T_CleanCustomers[Customer_ID],0)),"Unmatched") -> Fleet Expense Card | P118: =IFERROR(INDEX(T_CleanCustomers[Customer_Segment],MATCH(B118,T_CleanCustomers[Customer_ID],0)),"Unmatched") -> SME
A119: TXN0000118 | B119: CUST00015 | C119: =TRUE() -> TRUE | D119: 45883 | E119: 45870 | F119: Parking | G119: 4379.44 | H119: 127.13 | I119: =TRUE() -> TRUE | J119: Completed | K119: 127.13 | L119: United Kingdom | M119: =IFERROR(INDEX(T_CleanCustomers[Sales_Rep_ID],MATCH(B119,T_CleanCustomers[Customer_ID],0)),"Unmatched") -> REP006 | N119: =IFERROR(INDEX(T_CleanCustomers[Channel],MATCH(B119,T_CleanCustomers[Customer_ID],0)),"Unmatched") -> Direct Sales | O119: =IFERROR(INDEX(T_CleanCustomers[Product],MATCH(B119,T_CleanCustomers[Customer_ID],0)),"Unmatched") -> Fleet Expense Card | P119: =IFERROR(INDEX(T_CleanCustomers[Customer_Segment],MATCH(B119,T_CleanCustomers[Customer_ID],0)),"Unmatched") -> SME
A120: TXN0000119 | B120: CUST00015 | C120: =TRUE() -> TRUE | D120: 45904 | E120: 45901 | F120: Fuel | G120: 2181.37 | H120: 56.96 | I120: =TRUE() -> TRUE | J120: Completed | K120: 56.96 | L120: United Kingdom | M120: =IFERROR(INDEX(T_CleanCustomers[Sales_Rep_ID],MATCH(B120,T_CleanCustomers[Customer_ID],0)),"Unmatched") -> REP006 | N120: =IFERROR(INDEX(T_CleanCustomers[Channel],MATCH(B120,T_CleanCustomers[Customer_ID],0)),"Unmatched") -> Direct Sales | O120: =IFERROR(INDEX(T_CleanCustomers[Product],MATCH(B120,T_CleanCustomers[Customer_ID],0)),"Unmatched") -> Fleet Expense Card | P120: =IFERROR(INDEX(T_CleanCustomers[Customer_Segment],MATCH(B120,T_CleanCustomers[Customer_ID],0)),"Unmatched") -> SME
A121: TXN0000120 | B121: CUST00015 | C121: =TRUE() -> TRUE | D121: 45924 | E121: 45901 | F121: Lodging | G121: 4271.34 | H121: 102.75 | I121: =TRUE() -> TRUE | J121: Completed | K121: 102.75 | L121: United Kingdom | M121: =IFERROR(INDEX(T_CleanCustomers[Sales_Rep_ID],MATCH(B121,T_CleanCustomers[Customer_ID],0)),"Unmatched") -> REP006 | N121: =IFERROR(INDEX(T_CleanCustomers[Channel],MATCH(B121,T_CleanCustomers[Customer_ID],0)),"Unmatched") -> Direct Sales | O121: =IFERROR(INDEX(T_CleanCustomers[Product],MATCH(B121,T_CleanCustomers[Customer_ID],0)),"Unmatched") -> Fleet Expense Card | P121: =IFERROR(INDEX(T_CleanCustomers[Customer_Segment],MATCH(B121,T_CleanCustomers[Customer_ID],0)),"Unmatched") -> SME
A122: TXN0000121 | B122: CUST00015 | C122: =TRUE() -> TRUE | D122: 45934 | E122: 45931 | F122: Lodging | G122: 2363.7 | H122: 63.82 | I122: =TRUE() -> TRUE | J122: Completed | K122: 63.82 | L122: United Kingdom | M122: =IFERROR(INDEX(T_CleanCustomers[Sales_Rep_ID],MATCH(B122,T_CleanCustomers[Customer_ID],0)),"Unmatched") -> REP006 | N122: =IFERROR(INDEX(T_CleanCustomers[Channel],MATCH(B122,T_CleanCustomers[Customer_ID],0)),"Unmatched") -> Direct Sales | O122: =IFERROR(INDEX(T_CleanCustomers[Product],MATCH(B122,T_CleanCustomers[Customer_ID],0)),"Unmatched") -> Fleet Expense Card | P122: =IFERROR(INDEX(T_CleanCustomers[Customer_Segment],MATCH(B122,T_CleanCustomers[Customer_ID],0)),"Unmatched") -> SME
A123: TXN0000122 | B123: CUST00015 | C123: =TRUE() -> TRUE | D123: 45960 | E123: 45931 | F123: Lodging | G123: 2927.4 | H123: 88.42 | I123: =TRUE() -> TRUE | J123: Completed | K123: 88.42 | L123: United Kingdom | M123: =IFERROR(INDEX(T_CleanCustomers[Sales_Rep_ID],MATCH(B123,T_CleanCustomers[Customer_ID],0)),"Unmatched") -> REP006 | N123: =IFERROR(INDEX(T_CleanCustomers[Channel],MATCH(B123,T_CleanCustomers[Customer_ID],0)),"Unmatched") -> Direct Sales | O123: =IFERROR(INDEX(T_CleanCustomers[Product],MATCH(B123,T_CleanCustomers[Customer_ID],0)),"Unmatched") -> Fleet Expense Card | P123: =IFERROR(INDEX(T_CleanCustomers[Customer_Segment],MATCH(B123,T_CleanCustomers[Customer_ID],0)),"Unmatched") -> SME
A124: TXN0000123 | B124: CUST00015 | C124: =TRUE() -> TRUE | D124: 45953 | E124: 45931 | F124: Lodging | G124: 4254.25 | H124: 117.86 | I124: =TRUE() -> TRUE | J124: Completed | K124: 117.86 | L124: United Kingdom | M124: =IFERROR(INDEX(T_CleanCustomers[Sales_Rep_ID],MATCH(B124,T_CleanCustomers[Customer_ID],0)),"Unmatched") -> REP006 | N124: =IFERROR(INDEX(T_CleanCustomers[Channel],MATCH(B124,T_CleanCustomers[Customer_ID],0)),"Unmatched") -> Direct Sales | O124: =IFERROR(INDEX(T_CleanCustomers[Product],MATCH(B124,T_CleanCustomers[Customer_ID],0)),"Unmatched") -> Fleet Expense Card | P124: =IFERROR(INDEX(T_CleanCustomers[Customer_Segment],MATCH(B124,T_CleanCustomers[Customer_ID],0)),"Unmatched") -> SME
A125: TXN0000124 | B125: CUST00015 | C125: =TRUE() -> TRUE | D125: 45973 | E125: 45962 | F125: Fuel | G125: 4178.95 | H125: 127.75 | I125: =TRUE() -> TRUE | J125: Completed | K125: 127.75 | L125: United Kingdom | M125: =IFERROR(INDEX(T_CleanCustomers[Sales_Rep_ID],MATCH(B125,T_CleanCustomers[Customer_ID],0)),"Unmatched") -> REP006 | N125: =IFERROR(INDEX(T_CleanCustomers[Channel],MATCH(B125,T_CleanCustomers[Customer_ID],0)),"Unmatched") -> Direct Sales | O125: =IFERROR(INDEX(T_CleanCustomers[Product],MATCH(B125,T_CleanCustomers[Customer_ID],0)),"Unmatched") -> Fleet Expense Card | P125: =IFERROR(INDEX(T_CleanCustomers[Customer_Segment],MATCH(B125,T_CleanCustomers[Customer_ID],0)),"Unmatched") -> SME
...

Sheet Pivot
A3: Lead_Status | B3: Leads | D3: Leads | E3: Lead_Status | J3: Leads | K3: Lead_Status | R3: Market | S3: Leads | T3: Pipeline EUR | V3: Leads | W3: Qualified | X3: Opportunities | Y3: Wins
A4: Lost | B4: 707 | D4: Created_Month | E4: Lost | F4: New | G4: Opportunity | H4: Qualified | I4: Won | J4: Channel | K4: Lost | L4: New | M4: Opportunity | N4: Qualified | O4: Won | R4: Czech Republic | S4: 115 | T4: 261045.95 | V4: 1000 | W4: 702 | X4: 531 | Y4: 220
A5: New | B5: 25 | D5: 45658 | E5: 50 | I5: 18 | J5: Digital | K5: 192 | L5: 9 | M5: 5 | N5: 4 | O5: 22 | R5: France | S5: 181 | T5: 398977.78
A6: Opportunity | B6: 29 | D6: 45689 | E6: 60 | I6: 16 | J6: Direct Sales | K6: 164 | L6: 3 | M6: 8 | N6: 3 | O6: 92 | R6: Germany | S6: 286 | T6: 691633.16
A7: Qualified | B7: 19 | D7: 45717 | E7: 61 | I7: 22 | J7: Partner | K7: 152 | L7: 5 | M7: 8 | N7: 4 | O7: 44 | R7: Netherlands | S7: 164 | T7: 368682.84
A8: Won | B8: 220 | D8: 45748 | E8: 63 | I8: 14 | J8: Referral | K8: 65 | L8: 1 | M8: 5 | N8: 3 | O8: 34 | R8: United Kingdom | S8: 254 | T8: 533231.85
D9: 45778 | E9: 69 | I9: 23 | J9: Telesales | K9: 129 | L9: 6 | M9: 3 | N9: 5 | O9: 24
D10: 45809 | E10: 71 | I10: 15 | J10: Unknown | K10: 5 | L10: 1 | O10: 4
D11: 45839 | E11: 72 | I11: 16
D12: 45870 | E12: 70 | I12: 18
D13: 45901 | E13: 64 | I13: 18
D14: 45931 | E14: 62 | I14: 18
D15: 45962 | E15: 56 | H15: 3 | I15: 23
D16: 45992 | E16: 9 | F16: 25 | G16: 29 | H16: 16 | I16: 19
A30: Leads | B30: Lead_Status | J30: Customer_Segment | K30: Customers | L30: Activated | M30: AvgDays | P30: Customers | Q30: Customer_Status_Clean | V30: Customers | W30: Activated | X30: Churned | Y30: AvgDays
A31: Sales_Rep_ID | B31: Lost | C31: New | D31: Opportunity | E31: Qualified | F31: Won | J31: Enterprise | K31: 33 | L31: 32 | M31: 27.064516 | P31: Market | Q31: Active | R31: Churned | S31: Not Activated | T31: Not Activated (data issue) | V31: 220 | W31: 174 | X31: 13 | Y31: 25.05848
A32: REP001 | B32: 66 | C32: 3 | D32: 6 | E32: 3 | F32: 14 | J32: Mid-Market | K32: 64 | L32: 49 | M32: 25.666667 | P32: Czech Republic | Q32: 22 | R32: 3 | S32: 3
A33: REP002 | B33: 58 | C33: 4 | D33: 5 | E33: 1 | F33: 19 | J33: SME | K33: 115 | L33: 87 | M33: 24.988372 | P33: France | Q33: 34 | R33: 2 | S33: 3
A34: REP003 | B34: 77 | C34: 1 | D34: 1 | E34: 1 | F34: 26 | J34: Unclassified | K34: 8 | L34: 6 | M34: 10.833333 | P34: Germany | Q34: 35 | R34: 2 | S34: 20 | T34: 2
A35: REP004 | B35: 71 | C35: 1 | E35: 2 | F35: 12 | P35: Netherlands | Q35: 28 | R35: 6 | S35: 7
A36: REP005 | B36: 55 | C36: 3 | D36: 1 | E36: 3 | F36: 17 | P36: United Kingdom | Q36: 39 | R36: 3 | S36: 8 | T36: 3
A37: REP006 | B37: 59 | C37: 2 | D37: 2 | F37: 24
A38: REP007 | B38: 29 | C38: 2 | D38: 3 | E38: 1 | F38: 10
A39: REP008 | B39: 42 | D39: 4 | E39: 1 | F39: 14
A40: REP009 | B40: 40 | C40: 1 | F40: 16
A41: REP010 | B41: 20 | C41: 1 | D41: 1 | F41: 7
A42: REP011 | B42: 37 | C42: 1 | D42: 1 | E42: 1 | F42: 8
A43: REP012 | B43: 23 | C43: 1 | D43: 1 | F43: 13
A44: REP013 | B44: 43 | C44: 1 | E44: 1 | F44: 9
A45: REP014 | B45: 41 | C45: 2 | D45: 3 | E45: 1 | F45: 13
A46: REP015 | B46: 41 | C46: 2 | D46: 1 | E46: 4 | F46: 17
A47: REP999 | B47: 5 | F47: 1
A56: Transaction_Month | B56: Revenue | C56: Txns | F56: Channel_via_Customer | G56: Revenue | K56: Revenue | L56: Txns
A57: 45689 | B57: 5118.04 | C57: 13 | F57: Digital | G57: 54033.69 | K57: 507744.95 | L57: 1609
A58: 45717 | B58: 13574.55 | C58: 36 | F58: Direct Sales | G58: 190040.03
A59: 45748 | B59: 23741.43 | C59: 64 | F59: Partner | G59: 127442.08
A60: 45778 | B60: 32383.38 | C60: 91 | F60: Referral | G60: 81776.87
A61: 45809 | B61: 42829.8 | C61: 117 | F61: Telesales | G61: 54452.28
A62: 45839 | B62: 60369.83 | C62: 163 | F62: Unmatched | G62: 0
A63: 45870 | B63: 55415.95 | C63: 182
...

Sheet KPI_Summary
A1: KPI_Summary — funnel, activation, revenue, churn and target-attainment KPIs by month, market, channel, product, segment and sales rep
A2: All figures are live formulas (COUNTIFS / SUMIFS / AVERAGEIFS / SUMPRODUCT) referencing Clean_Leads, Clean_Customers, Clean_Transactions and Targets. Recalculates automatically if source data changes.
A4: 1. Monthly Funnel, Win Rate & Revenue Trend (2025)
A6: Month | B6: Leads | C6: Qualified | D6: Opportunities | E6: Won | F6: Qualification Rate | G6: Opportunity Rate | H6: Win Rate | I6: Completed Revenue (EUR) | J6: Revenue Target (EUR) | K6: Revenue Attainment
A7: 45658 | B7: =COUNTIFS(T_CleanLeads[Created_Month],A7) -> 68 | C7: =COUNTIFS(T_CleanLeads[Created_Month],A7,T_CleanLeads[Qualified_Flag],"Yes") -> 59 | D7: =COUNTIFS(T_CleanLeads[Created_Month],A7,T_CleanLeads[Opportunity_Date],"<>") -> 43 | E7: =COUNTIFS(T_CleanLeads[Created_Month],A7,T_CleanLeads[Lead_Status],"Won") -> 18 | F7: =IFERROR(C7/B7,0) -> 0.86764706 | G7: =IFERROR(D7/C7,0) -> 0.72881356 | H7: =IFERROR(E7/D7,0) -> 0.41860465 | I7: =SUMIFS(T_CleanTxns[Revenue_Usable],T_CleanTxns[Transaction_Month],A7) -> 0 | J7: =SUMIFS(Targets!$F$3:$F$62,Targets!$A$3:$A$62,A7) -> 1062000 | K7: =IFERROR(I7/J7,0) -> 0
A8: 45689 | B8: =COUNTIFS(T_CleanLeads[Created_Month],A8) -> 76 | C8: =COUNTIFS(T_CleanLeads[Created_Month],A8,T_CleanLeads[Qualified_Flag],"Yes") -> 54 | D8: =COUNTIFS(T_CleanLeads[Created_Month],A8,T_CleanLeads[Opportunity_Date],"<>") -> 39 | E8: =COUNTIFS(T_CleanLeads[Created_Month],A8,T_CleanLeads[Lead_Status],"Won") -> 16 | F8: =IFERROR(C8/B8,0) -> 0.71052632 | G8: =IFERROR(D8/C8,0) -> 0.72222222 | H8: =IFERROR(E8/D8,0) -> 0.41025641 | I8: =SUMIFS(T_CleanTxns[Revenue_Usable],T_CleanTxns[Transaction_Month],A8) -> 5118.04 | J8: =SUMIFS(Targets!$F$3:$F$62,Targets!$A$3:$A$62,A8) -> 1062000 | K8: =IFERROR(I8/J8,0) -> 0.0048192467
A9: 45717 | B9: =COUNTIFS(T_CleanLeads[Created_Month],A9) -> 83 | C9: =COUNTIFS(T_CleanLeads[Created_Month],A9,T_CleanLeads[Qualified_Flag],"Yes") -> 55 | D9: =COUNTIFS(T_CleanLeads[Created_Month],A9,T_CleanLeads[Opportunity_Date],"<>") -> 45 | E9: =COUNTIFS(T_CleanLeads[Created_Month],A9,T_CleanLeads[Lead_Status],"Won") -> 22 | F9: =IFERROR(C9/B9,0) -> 0.6626506 | G9: =IFERROR(D9/C9,0) -> 0.81818182 | H9: =IFERROR(E9/D9,0) -> 0.48888889 | I9: =SUMIFS(T_CleanTxns[Revenue_Usable],T_CleanTxns[Transaction_Month],A9) -> 13574.55 | J9: =SUMIFS(Targets!$F$3:$F$62,Targets!$A$3:$A$62,A9) -> 1180000 | K9: =IFERROR(I9/J9,0) -> 0.011503856
A10: 45748 | B10: =COUNTIFS(T_CleanLeads[Created_Month],A10) -> 77 | C10: =COUNTIFS(T_CleanLeads[Created_Month],A10,T_CleanLeads[Qualified_Flag],"Yes") -> 54 | D10: =COUNTIFS(T_CleanLeads[Created_Month],A10,T_CleanLeads[Opportunity_Date],"<>") -> 45 | E10: =COUNTIFS(T_CleanLeads[Created_Month],A10,T_CleanLeads[Lead_Status],"Won") -> 14 | F10: =IFERROR(C10/B10,0) -> 0.7012987 | G10: =IFERROR(D10/C10,0) -> 0.83333333 | H10: =IFERROR(E10/D10,0) -> 0.31111111 | I10: =SUMIFS(T_CleanTxns[Revenue_Usable],T_CleanTxns[Transaction_Month],A10) -> 23741.43 | J10: =SUMIFS(Targets!$F$3:$F$62,Targets!$A$3:$A$62,A10) -> 1180000 | K10: =IFERROR(I10/J10,0) -> 0.020119856
A11: 45778 | B11: =COUNTIFS(T_CleanLeads[Created_Month],A11) -> 92 | C11: =COUNTIFS(T_CleanLeads[Created_Month],A11,T_CleanLeads[Qualified_Flag],"Yes") -> 66 | D11: =COUNTIFS(T_CleanLeads[Created_Month],A11,T_CleanLeads[Opportunity_Date],"<>") -> 49 | E11: =COUNTIFS(T_CleanLeads[Created_Month],A11,T_CleanLeads[Lead_Status],"Won") -> 23 | F11: =IFERROR(C11/B11,0) -> 0.7173913 | G11: =IFERROR(D11/C11,0) -> 0.74242424 | H11: =IFERROR(E11/D11,0) -> 0.46938776 | I11: =SUMIFS(T_CleanTxns[Revenue_Usable],T_CleanTxns[Transaction_Month],A11) -> 32383.38 | J11: =SUMIFS(Targets!$F$3:$F$62,Targets!$A$3:$A$62,A11) -> 1180000 | K11: =IFERROR(I11/J11,0) -> 0.027443542
A12: 45809 | B12: =COUNTIFS(T_CleanLeads[Created_Month],A12) -> 86 | C12: =COUNTIFS(T_CleanLeads[Created_Month],A12,T_CleanLeads[Qualified_Flag],"Yes") -> 60 | D12: =COUNTIFS(T_CleanLeads[Created_Month],A12,T_CleanLeads[Opportunity_Date],"<>") -> 44 | E12: =COUNTIFS(T_CleanLeads[Created_Month],A12,T_CleanLeads[Lead_Status],"Won") -> 15 | F12: =IFERROR(C12/B12,0) -> 0.69767442 | G12: =IFERROR(D12/C12,0) -> 0.73333333 | H12: =IFERROR(E12/D12,0) -> 0.34090909 | I12: =SUMIFS(T_CleanTxns[Revenue_Usable],T_CleanTxns[Transaction_Month],A12) -> 42829.8 | J12: =SUMIFS(Targets!$F$3:$F$62,Targets!$A$3:$A$62,A12) -> 1180000 | K12: =IFERROR(I12/J12,0) -> 0.036296441
A13: 45839 | B13: =COUNTIFS(T_CleanLeads[Created_Month],A13) -> 88 | C13: =COUNTIFS(T_CleanLeads[Created_Month],A13,T_CleanLeads[Qualified_Flag],"Yes") -> 62 | D13: =COUNTIFS(T_CleanLeads[Created_Month],A13,T_CleanLeads[Opportunity_Date],"<>") -> 45 | E13: =COUNTIFS(T_CleanLeads[Created_Month],A13,T_CleanLeads[Lead_Status],"Won") -> 16 | F13: =IFERROR(C13/B13,0) -> 0.70454545 | G13: =IFERROR(D13/C13,0) -> 0.72580645 | H13: =IFERROR(E13/D13,0) -> 0.35555556 | I13: =SUMIFS(T_CleanTxns[Revenue_Usable],T_CleanTxns[Transaction_Month],A13) -> 60369.83 | J13: =SUMIFS(Targets!$F$3:$F$62,Targets!$A$3:$A$62,A13) -> 1180000 | K13: =IFERROR(I13/J13,0) -> 0.051160873
A14: 45870 | B14: =COUNTIFS(T_CleanLeads[Created_Month],A14) -> 88 | C14: =COUNTIFS(T_CleanLeads[Created_Month],A14,T_CleanLeads[Qualified_Flag],"Yes") -> 58 | D14: =COUNTIFS(T_CleanLeads[Created_Month],A14,T_CleanLeads[Opportunity_Date],"<>") -> 45 | E14: =COUNTIFS(T_CleanLeads[Created_Month],A14,T_CleanLeads[Lead_Status],"Won") -> 18 | F14: =IFERROR(C14/B14,0) -> 0.65909091 | G14: =IFERROR(D14/C14,0) -> 0.77586207 | H14: =IFERROR(E14/D14,0) -> 0.4 | I14: =SUMIFS(T_CleanTxns[Revenue_Usable],T_CleanTxns[Transaction_Month],A14) -> 55415.95 | J14: =SUMIFS(Targets!$F$3:$F$62,Targets!$A$3:$A$62,A14) -> 1180000 | K14: =IFERROR(I14/J14,0) -> 0.046962669
A15: 45901 | B15: =COUNTIFS(T_CleanLeads[Created_Month],A15) -> 82 | C15: =COUNTIFS(T_CleanLeads[Created_Month],A15,T_CleanLeads[Qualified_Flag],"Yes") -> 61 | D15: =COUNTIFS(T_CleanLeads[Created_Month],A15,T_CleanLeads[Opportunity_Date],"<>") -> 47 | E15: =COUNTIFS(T_CleanLeads[Created_Month],A15,T_CleanLeads[Lead_Status],"Won") -> 18 | F15: =IFERROR(C15/B15,0) -> 0.74390244 | G15: =IFERROR(D15/C15,0) -> 0.7704918 | H15: =IFERROR(E15/D15,0) -> 0.38297872 | I15: =SUMIFS(T_CleanTxns[Revenue_Usable],T_CleanTxns[Transaction_Month],A15) -> 65443.06 | J15: =SUMIFS(Targets!$F$3:$F$62,Targets!$A$3:$A$62,A15) -> 1321600 | K15: =IFERROR(I15/J15,0) -> 0.049518054
A16: 45931 | B16: =COUNTIFS(T_CleanLeads[Created_Month],A16) -> 80 | C16: =COUNTIFS(T_CleanLeads[Created_Month],A16,T_CleanLeads[Qualified_Flag],"Yes") -> 50 | D16: =COUNTIFS(T_CleanLeads[Created_Month],A16,T_CleanLeads[Opportunity_Date],"<>") -> 35 | E16: =COUNTIFS(T_CleanLeads[Created_Month],A16,T_CleanLeads[Lead_Status],"Won") -> 18 | F16: =IFERROR(C16/B16,0) -> 0.625 | G16: =IFERROR(D16/C16,0) -> 0.7 | H16: =IFERROR(E16/D16,0) -> 0.51428571 | I16: =SUMIFS(T_CleanTxns[Revenue_Usable],T_CleanTxns[Transaction_Month],A16) -> 62657.36 | J16: =SUMIFS(Targets!$F$3:$F$62,Targets!$A$3:$A$62,A16) -> 1321600 | K16: =IFERROR(I16/J16,0) -> 0.04741023
A17: 45962 | B17: =COUNTIFS(T_CleanLeads[Created_Month],A17) -> 82 | C17: =COUNTIFS(T_CleanLeads[Created_Month],A17,T_CleanLeads[Qualified_Flag],"Yes") -> 59 | D17: =COUNTIFS(T_CleanLeads[Created_Month],A17,T_CleanLeads[Opportunity_Date],"<>") -> 46 | E17: =COUNTIFS(T_CleanLeads[Created_Month],A17,T_CleanLeads[Lead_Status],"Won") -> 23 | F17: =IFERROR(C17/B17,0) -> 0.7195122 | G17: =IFERROR(D17/C17,0) -> 0.77966102 | H17: =IFERROR(E17/D17,0) -> 0.5 | I17: =SUMIFS(T_CleanTxns[Revenue_Usable],T_CleanTxns[Transaction_Month],A17) -> 68212.31 | J17: =SUMIFS(Targets!$F$3:$F$62,Targets!$A$3:$A$62,A17) -> 1321600 | K17: =IFERROR(I17/J17,0) -> 0.051613431
